<?xml version="1.0" ?>
<!-- =================================================================================== -->
<!-- |    This document was autogenerated by xacro from mtconnect_m16ib20_demo.xacro   | -->
<!-- |    EDITING THIS FILE BY HAND IS NOT RECOMMENDED                                 | -->
<!-- =================================================================================== -->
<robot name="NIST_Robot" xmlns:xacro="http://ros.org/wiki/xacro">
  <!-- instantiating xacros -->
  <link name="base_link">
    <visual>
      <origin rpy="0 0 0" xyz="0 0 0"/>
      <geometry>
        <mesh filename="package://fanuc_config/meshes/m_16iB20/visual/base_link.STL"/>
      </geometry>
      <material name="">
        <color rgba="1 1 0 1"/>
      </material>
    </visual>
    <collision>
      <origin rpy="0 0 0" xyz="0 0 0"/>
      <geometry>
        <mesh filename="package://fanuc_config/meshes/m_16iB20/collision/base_link.STL"/>
      </geometry>
    </collision>
  </link>
  <link name="link_1">
    <visual>
      <origin rpy="0 0 0" xyz="0 0 0"/>
      <geometry>
        <mesh filename="package://fanuc_config/meshes/m_16iB20/visual/Link_1.STL"/>
      </geometry>
      <material name="">
        <color rgba="1 1 0 1"/>
      </material>
    </visual>
    <collision>
      <origin rpy="0 0 0" xyz="0 0 0"/>
      <geometry>
        <mesh filename="package://fanuc_config/meshes/m_16iB20/collision/Link_1.STL"/>
      </geometry>
    </collision>
  </link>
  <link name="link_2">
    <visual>
      <origin rpy="0 0 0" xyz="0 0 0"/>
      <geometry>
        <mesh filename="package://fanuc_config/meshes/m_16iB20/visual/Link_2.STL"/>
      </geometry>
      <material name="">
        <color rgba="1 1 0 1"/>
      </material>
    </visual>
    <collision>
      <origin rpy="0 0 0" xyz="0 0 0"/>
      <geometry>
        <mesh filename="package://fanuc_config/meshes/m_16iB20/collision/Link_2.STL"/>
      </geometry>
    </collision>
  </link>
  <link name="link_3">
    <visual>
      <origin rpy="0 0 0" xyz="0 0 0"/>
      <geometry>
        <mesh filename="package://fanuc_config/meshes/m_16iB20/visual/Link_3.STL"/>
      </geometry>
      <material name="">
        <color rgba="1 1 0 1"/>
      </material>
    </visual>
    <collision>
      <origin rpy="0 0 0" xyz="0 0 0"/>
      <geometry>
        <mesh filename="package://fanuc_config/meshes/m_16iB20/collision/Link_3.STL"/>
      </geometry>
    </collision>
  </link>
  <link name="link_4">
    <visual>
      <origin rpy="0 0 0" xyz="0 0 0"/>
      <geometry>
        <mesh filename="package://fanuc_config/meshes/m_16iB20/visual/Link_4.STL"/>
      </geometry>
      <material name="">
        <color rgba="1 1 0 1"/>
      </material>
    </visual>
    <collision>
      <origin rpy="0 0 0" xyz="0 0 0"/>
      <geometry>
        <mesh filename="package://fanuc_config/meshes/m_16iB20/collision/Link_4.STL"/>
      </geometry>
    </collision>
  </link>
  <link name="link_5">
    <visual>
      <origin rpy="0 0 0" xyz="0 0 0"/>
      <geometry>
        <mesh filename="package://fanuc_config/meshes/m_16iB20/visual/Link_5.STL"/>
      </geometry>
      <material name="">
        <color rgba="1 1 0 1"/>
      </material>
    </visual>
    <collision>
      <origin rpy="0 0 0" xyz="0 0 0"/>
      <geometry>
        <mesh filename="package://fanuc_config/meshes/m_16iB20/collision/Link_5.STL"/>
      </geometry>
    </collision>
  </link>
  <link name="link_6">
    <visual>
      <origin rpy="0 0 0" xyz="0 0 0"/>
      <geometry>
        <mesh filename="package://fanuc_config/meshes/m_16iB20/visual/Link_6.STL"/>
      </geometry>
      <material name="">
        <color rgba="1 1 0 1"/>
      </material>
    </visual>
    <collision>
      <origin rpy="0 0 0" xyz="0 0 0"/>
      <geometry>
        <mesh filename="package://fanuc_config/meshes/m_16iB20/collision/Link_6.STL"/>
      </geometry>
    </collision>
  </link>
  <link name="tool0"/>
  <joint name="joint_1" type="revolute">
    <origin rpy="0 0 0" xyz="0 0 0.245"/>
    <parent link="base_link"/>
    <child link="link_1"/>
    <axis xyz="0 0 1"/>
    <limit effort="0" lower="-2.967" upper="2.967" velocity="2.879"/>
  </joint>
  <joint name="joint_2" type="revolute">
    <origin rpy="0 0 0" xyz="0.15 0.18759 0.28"/>
    <parent link="link_1"/>
    <child link="link_2"/>
    <axis xyz="0 1 0"/>
    <limit effort="0" lower="-1.38" upper="2.78" velocity="2.879"/>
  </joint>
  <joint name="joint_3" type="revolute">
    <origin rpy="0 0 0" xyz="0 -0.18759 0.77"/>
    <parent link="link_2"/>
    <child link="link_3"/>
    <axis xyz="0 -1 0"/>
    <limit effort="0" lower="-4.08" upper="1.38" velocity="3.054"/>
  </joint>
  <joint name="joint_4" type="revolute">
    <origin rpy="0 0 0" xyz="0.18425 0 0.1"/>
    <parent link="link_3"/>
    <child link="link_4"/>
    <axis xyz="-1 0 0"/>
    <limit effort="0" lower="-3.48" upper="3.48" velocity="6.108"/>
  </joint>
  <joint name="joint_5" type="revolute">
    <origin rpy="0 0 0" xyz="0.55575 0 0"/>
    <parent link="link_4"/>
    <child link="link_5"/>
    <axis xyz="0 -1 0"/>
    <limit effort="0" lower="-2.43" upper="2.43" velocity="5.934"/>
  </joint>
  <joint name="joint_6" type="revolute">
    <origin rpy="0 0 0" xyz="0.1 0 0"/>
    <parent link="link_5"/>
    <child link="link_6"/>
    <axis xyz="-1 0 0"/>
    <limit effort="0" lower="-7.84" upper="7.84" velocity="9.075"/>
  </joint>
  <joint name="joint_6-tool0" type="fixed">
    <parent link="link_6"/>
    <child link="tool0"/>
    <origin rpy="0 0 0" xyz="0 0 0"/>
  </joint>
  <!-- parameters -->
  <!-- color definitions -->
  <material name="blue">
    <color rgba="0 0 1 1"/>
  </material>
  <material name="yellow">
    <color rgba="1 1 0 1"/>
  </material>
  <material name="orange">
    <color rgba="1 0.66 0.48 1"/>
  </material>
  <material name="red">
    <color rgba="1 0 0 1"/>
  </material>
  <material name="light_blue">
    <color rgba="0.78 0.94 0.965 1"/>
  </material>
  <!-- link definitions -->
  <link name="world_frame"/>
  <!--link name="palm"/-->
  <link name="tcp_frame"/>
  <link name="robot_platform_link">
    <visual>
      <origin rpy="0 0 0" xyz="0.0 0.0 -0.05"/>
      <geometry>
        <box size="0.5 0.5 0.1"/>
      </geometry>
      <material name="orange"/>
    </visual>
  </link>
  <link name="end_effector_link">
    <visual>
      <origin rpy="0 0 0" xyz="0.0 0.0 0.175"/>
      <geometry>
        <box size="0.1 0.1 0.35"/>
      </geometry>
      <material name="light_blue"/>
    </visual>
  </link>
  <link name="cnc_link">
    <visual>
      <geometry>
        <mesh filename="package://mtconnect_example_launch/meshes/cnc_lathe.STL"/>
      </geometry>
      <material name="red"/>
    </visual>
  </link>
  <!-- joint definitions -->
  <joint name="world_to_platform_joint" type="fixed">
    <origin rpy="3.1417 0 0" xyz="0.2 0 2"/>
    <parent link="world_frame"/>
    <child link="robot_platform_link"/>
  </joint>
  <joint name="world_to_cnc_joint" type="fixed">
    <origin rpy="1.5708 0 -1.5708" xyz="2.6 1.325 -0.45"/>
    <parent link="world_frame"/>
    <child link="cnc_link"/>
  </joint>
  <joint name="platform_to_base_joint" type="fixed">
    <origin rpy="0 0 0" xyz="0 0 0"/>
    <parent link="robot_platform_link"/>
    <child link="base_link"/>
  </joint>
  <joint name="tool_to_end_effector" type="fixed">
    <origin rpy="0 1.5708 0" xyz="0 0 0"/>
    <parent link="tool0"/>
    <child link="end_effector_link"/>
  </joint>
  <joint name="tool_to_tcp" type="fixed">
    <origin rpy="0 0 0" xyz="0.35 0 0"/>
    <parent link="tool0"/>
    <child link="tcp_frame"/>
  </joint>
</robot>

